Workbook

Sheet ORÇAMENTO SINTÉTICO - SB-A2
B1: ORÇAMENTO SINTÉTICO SEM DESONERAÇÃO FONTE: SANEPAR
B3: #VALUE! | F3: ELABORAÇÃO DE ORÇAMENTO PARA ESTAÇÃO ELEVATÓRIA DE ESGOTO | I3: CIDADE: | K3: Altamira do Paraná | N3: #VALUE!
I4: ESTADO: | K4: Paraná
I5: SISTEMA: | K5: EEE
I6: MICROBACIA / ÁREA: | K6: SB-A2
I7: DATA: | K7: =TODAY() -> 46197
I8: REVISÃO: | K8: R00
I9: ANÁLISE TÉCNICA
I10: ELABORAÇÃO: | K10: Daniel Gama
I11: ENG. RESPONSÁVEL: | K11: Rodrigo A. Zanatta
I12: CREA: | K12: SC-0680240/D
B13: Código | E13: Descrição | G13: Tipo | H13: Origem | I13: Quant. | J13: Un. Med. | K13: Valor Unitário | M13: BDI | N13: Preço Unit. C/ BDI | O13: Custo Total | P13: Preço Total C/ BDI
E14: SERVIÇOS INICIAIS | P14: =P15+P20+P29 -> 16719.939
B15: 001 | E15: CANTEIRO DE OBRAS | P15: =P16+P18 -> 6023.8133
B16: 001.004 | E16: PROTEÇÃO DA ÁREA | K16: =[1]REF_TAB_PREÇOS_SANEPAR!I32 | P16: =SUBTOTAL(9,P17:P17) -> 3526.0111
B17: 001004003 | E17: Tapume de chapa de madeira compensada | G17: Mat | H17: Sanepar | I17: =Memorial!D5 -> 23 | J17: m | K17: =[1]REF_TAB_PREÇOS_SANEPAR!I35 -> 135.68 | M17: =IF(G17="", "", IFERROR(IF(G17="Mat", BDI!C$31, IF(G17="MO", BDI!C$17)), "")) -> 0.1299 | N17: =IF(K17="","",K17*(1+M17)) -> 153.30483 | O17: =K17*I17 -> 3120.64 | P17: =N17*I17 -> 3526.0111
B18: 001.005 | E18: PLACA DE OBRA | K18: =[1]REF_TAB_PREÇOS_SANEPAR!I37 | P18: =SUBTOTAL(9,P19) -> 2497.8021
B19: 001005001 | E19: Em chapa metálica | G19: Mat | H19: Sanepar | I19: 4 | J19: m² | K19: =[1]REF_TAB_PREÇOS_SANEPAR!I38 -> 552.66 | M19: =IF(G19="", "", IFERROR(IF(G19="Mat", BDI!C$31, IF(G19="MO", BDI!C$17)), "")) -> 0.1299 | N19: =IF(K19="","",K19*(1+M19)) -> 624.45053 | O19: =K19*I19 -> 2210.64 | P19: =N19*I19 -> 2497.8021
B20: 002 | E20: SERVIÇOS TÉCNICOS | K20: =[1]REF_TAB_PREÇOS_SANEPAR!I39 | P20: =P21+P23+P25+P27 -> 9702.1655
B21: 002.001 | E21: TOPOGRAFIA E GEODÉSIA - SERVIÇOS | K21: =[1]REF_TAB_PREÇOS_SANEPAR!I40 | P21: =SUBTOTAL(9,P22:P22) -> 86.346264
B22: 002001043 | E22: Locação da obra com auxílio de equipamento topográfico | G22: MO | H22: Sanepar | I22: =Memorial!C10 -> 25.5 | J22: m² | K22: =[1]REF_TAB_PREÇOS_SANEPAR!I83 -> 2.72 | M22: =IF(G22="", "", IFERROR(IF(G22="Mat", BDI!C$31, IF(G22="MO", BDI!C$17)), "")) -> 0.2449 | N22: =IF(K22="","",K22*(1+M22)) -> 3.386128 | O22: =K22*I22 -> 69.36 | P22: =N22*I22 -> 86.346264
B23: 002.004 | E23: SONDAGEM A PERCUSSÃO | K23: =[1]REF_TAB_PREÇOS_SANEPAR!I138 | M23: =IF(G23="", "", IFERROR(IF(G23="Mat", [1]BDI!C$31, IF(G23="MO", [1]BDI!C$17)), "")) | P23: =SUBTOTAL(9,P24:P24) -> 9047.622
B24: 002004002 | E24: Perfuração em solo (SPT) com estadia da equipe | G24: MO | H24: Sanepar | I24: 25 | J24: m | K24: =[1]REF_TAB_PREÇOS_SANEPAR!I140 -> 290.71 | M24: =IF(G24="", "", IFERROR(IF(G24="Mat", [1]BDI!C$31, IF(G24="MO", [1]BDI!C$17)), "")) -> 0.2449 | N24: =IF(K24="","",K24*(1+M24)) -> 361.90488 | O24: =K24*I24 -> 7267.75 | P24: =N24*I24 -> 9047.622
B25: 002.006 | E25: SONDAGEM A TRADO | K25: =[1]REF_TAB_PREÇOS_SANEPAR!I160 | P25: =SUBTOTAL(9,P26:P26) -> 376.33327
B26: 002006001 | E26: Perfuração em solo (trado) sem estadia da equipe - Cidade Pólo | G26: MO | H26: Sanepar | I26: 5 | J26: m | K26: =[1]REF_TAB_PREÇOS_SANEPAR!I161 -> 60.46 | M26: =IF(G26="", "", IFERROR(IF(G26="Mat", BDI!C$31, IF(G26="MO", BDI!C$17)), "")) -> 0.2449 | N26: =IF(K26="","",K26*(1+M26)) -> 75.266654 | O26: =K26*I26 -> 302.3 | P26: =N26*I26 -> 376.33327
B27: 002.007 | E27: CADASTRO DE OBRAS | K27: =[1]REF_TAB_PREÇOS_SANEPAR!I167 | P27: =SUBTOTAL(9,P28:P28) -> 191.86399
B28: 002007005 | E28: Cadastro de obra localizada "As Built" | G28: MO | H28: Sanepar | I28: 1 | J28: ud | K28: =[1]REF_TAB_PREÇOS_SANEPAR!I172 -> 154.12 | M28: =IF(G28="", "", IFERROR(IF(G28="Mat", BDI!C$31, IF(G28="MO", BDI!C$17)), "")) -> 0.2449 | N28: =IF(K28="","",K28*(1+M28)) -> 191.86399 | O28: =K28*I28 -> 154.12 | P28: =N28*I28 -> 191.86399
B29: 003 | E29: SERVIÇOS PRELIMINARES | K29: =[1]REF_TAB_PREÇOS_SANEPAR!I173 | P29: =P30+P32+P35 -> 993.96039
B30: 003.002 | E30: ACESSO PROVISÓRIO | K30: =[1]REF_TAB_PREÇOS_SANEPAR!I184 | P30: =SUBTOTAL(9,P31) -> 37.658225
B31: 003002001 | E31: Acesso provisório | G31: MO | H31: Sanepar | I31: 5 | J31: m² | K31: =[1]REF_TAB_PREÇOS_SANEPAR!I185 -> 6.05 | M31: =IF(G31="", "", IFERROR(IF(G31="Mat", BDI!C$31, IF(G31="MO", BDI!C$17)), "")) -> 0.2449 | N31: =IF(K31="","",K31*(1+M31)) -> 7.531645 | O31: =K31*I31 -> 30.25 | P31: =N31*I31 -> 37.658225
B32: 003.005 | E32: SINALIZAÇÃO DE SEGURANÇA | K32: =[1]REF_TAB_PREÇOS_SANEPAR!I201 | P32: =SUBTOTAL(9,P33:P34) -> 55.613678
B33: 003005001 | E33: Fita plástica | G33: Mat | H33: Sanepar | I33: =Memorial!D5 -> 23 | J33: m | K33: =[1]REF_TAB_PREÇOS_SANEPAR!I202 -> 0.3 | M33: =IF(G33="", "", IFERROR(IF(G33="Mat", BDI!C$31, IF(G33="MO", BDI!C$17)), "")) -> 0.1299 | N33: =IF(K33="","",K33*(1+M33)) -> 0.33897 | O33: =K33*I33 -> 6.9 | P33: =N33*I33 -> 7.79631
B34: 003005004 | E34: Tapume em tela plástica | G34: Mat | H34: Sanepar | I34: =Memorial!D5 -> 23 | J34: m | K34: =[1]REF_TAB_PREÇOS_SANEPAR!I205 -> 1.84 | M34: =IF(G34="", "", IFERROR(IF(G34="Mat", BDI!C$31, IF(G34="MO", BDI!C$17)), "")) -> 0.1299 | N34: =IF(K34="","",K34*(1+M34)) -> 2.079016 | O34: =K34*I34 -> 42.32 | P34: =N34*I34 -> 47.817368
B35: 003.006 | E35: SINALIZAÇÃO DE TRÂNSITO | K35: =[1]REF_TAB_PREÇOS_SANEPAR!I206 | P35: =SUBTOTAL(9,P36:P37) -> 900.68849
B36: 003006001 | E36: Placa de advertência 1,00 x 1,00 m | G36: Mat | H36: Sanepar | I36: 2 | J36: ud | K36: =[1]REF_TAB_PREÇOS_SANEPAR!I207 -> 151.33 | M36: =IF(G36="", "", IFERROR(IF(G36="Mat", BDI!C$31, IF(G36="MO", BDI!C$17)), "")) -> 0.1299 | N36: =IF(K36="","",K36*(1+M36)) -> 170.98777 | O36: =K36*I36 -> 302.66 | P36: =N36*I36 -> 341.97553
B37: 003006002 | E37: Placa de advertência 1,00 x 2,00 m | G37: Mat | H37: Sanepar | I37: 2 | J37: ud | K37: =[1]REF_TAB_PREÇOS_SANEPAR!I208 -> 247.24 | M37: =IF(G37="", "", IFERROR(IF(G37="Mat", BDI!C$31, IF(G37="MO", BDI!C$17)), "")) -> 0.1299 | N37: =IF(K37="","",K37*(1+M37)) -> 279.35648 | O37: =K37*I37 -> 494.48 | P37: =N37*I37 -> 558.71295
E38: POÇO | P38: =P39+P44+P57+P66+P69 -> 220648.92
B39: 004 | E39: MOVIMENTO DE SOLOS | K39: =[1]REF_TAB_PREÇOS_SANEPAR!I249 | P39: =P40+P42 -> 1387.3813
B40: 004.007 | E40: ESCAVAÇÃO MECÂNICA, NÃO EM VALAS, EM QUALQUER TIPO DE SOLO, EXCETO ROCHA | K40: =[1]REF_TAB_PREÇOS_SANEPAR!I296 | P40: =SUBTOTAL(9,P41:P41) -> 874.25592
B41: 004007002 | E41: Solos em geral, profundidade 0 m < h = 4 m | G41: MO | H41: Sanepar | I41: =Memorial!G6 -> 45.9 | J41: m³ | K41: =[1]REF_TAB_PREÇOS_SANEPAR!I298 -> 15.3 | M41: =IF(G41="", "", IFERROR(IF(G41="Mat", BDI!C$31, IF(G41="MO", BDI!C$17)), "")) -> 0.2449 | N41: =IF(K41="","",K41*(1+M41)) -> 19.04697 | O41: =K41*I41 -> 702.27 | P41: =N41*I41 -> 874.25592
...

Sheet BDI
A1: COMPOSIÇÃO DE BDI E BASE DE PREÇOS | E1: CUSTO DIRETO: | F1: ='ORÇAMENTO SINTÉTICO - PA4'!O305 -> 344407.41
A2: COMPOSIÇÃO DO BDI PARA MODALIDADE A PREÇO UNITÁRIO
A3: BASE DE CÁLCULO: Acórdão nº 2.622/2013 - TCU Plenário (TC 036.076/2011-2) FÓRMULA: Onde: BDI = LDI: bonificações e despesas indiretas (BDI) ou lucros e despesas indretas (LDI) AC: Taxa de rateio da administração central S: Taxa representativa de seguros R: Riscos e imprevistos G: Taxa que representa o ônus das garantias exigidas em edital DF: Taxa representativa das despesas financeiras L: Remuneração bruta do construtor I: Taxa representativa dos tributos CP: Tributos (COFINS e PIS) ISS: Tributos (ISS, variável de acordo com o município) CPRB: Tributos (Contribuição Previdenciária sobre a Receita Bruta)
AF4: Largura Vala | AG4: =(AG5+AG6+AG7+AG8) -> 0.5
A5: COMPOSIÇÃO DO BDI 1 - OBRAS E SERVIÇOS | AF5: Diâmetro | AG5: 0.15
A6: CONSTRUÇÃO DE REDES DE ABASTECIMENTO DE ÁGUA, COLETA DE ESGOTO E CONSTRUÇÕES CORRELATAS | AF6: SL | AG6: 0.35
A7: SIGLA | B7: DISCRIMINAÇÃO DAS PARCELAS | C7: BDI - SEM DESONERAÇÃO | AF7: X
A8: AC | B8: Administração Central | C8: {=_xlfn.IFS($F$1<=150000,0.055,$F$1<=1500000,0.05,$F$1>1500000,0.035)} -> 0.05 | AF8: Y | AG8: 0
A9: SG | B9: Seguro e Garantia | C9: {=_xlfn.IFS($F$1<=150000,0.007,$F$1<=1500000,0.005,$F$1>1500000,0.0035)} -> 0.005
A10: R | B10: Risco | C10: {=_xlfn.IFS($F$1<=150000,0.015,$F$1<=1500000,0.013,$F$1>1500000,0.01)} -> 0.013
A11: DF | B11: Despesas Financeiras | C11: {=_xlfn.IFS($F$1<=150000,0.008,$F$1<=1500000,0.0075,$F$1>1500000,0.007)} -> 0.0075
A12: L | B12: Lucro | C12: {=_xlfn.IFS($F$1<=150000,0.085,$F$1<=1500000,0.08,$F$1>1500000,0.065)} -> 0.08
A13: I | B13: COFINS | C13: 0.03
B14: PIS | C14: 0.0065
B15: ISS | C15: 0.03 | E15: ISS
B16: CRPB ( 0% ou 3,6% - Desoneração) | C16: 0
A17: TOTAL BDI 1 - OBRAS E SERVIÇOS | C17: =ROUND(((1+C8+C9+C10)*(1+C11)*(1+C12)/(1-C13-C14-C15-C16))-1,4) -> 0.2449
A19: C0MPOSIÇÃO DO BDI 2 - FORNECIMENTO DE MATERIAIS E EQUIPAMENTOS
A20: CONSTRUÇÃO DE REDES DE ABASTECIMENTO DE ÁGUA, COLETA DE ESGOTO E CONSTRUÇÕES CORRELATAS
A21: SIGLA | B21: DISCRIMINAÇÃO DAS PARCELAS | C21: BDI - SEM DESONERAÇÃO
A22: AC | B22: Administração Central | C22: {=_xlfn.IFS($F$1<=150000,0.035,$F$1<=1500000,0.025,$F$1>1500000,0.01)} -> 0.025
A23: SG | B23: Seguro e Garantia | C23: {=_xlfn.IFS($F$1<=150000,0.008,$F$1<=1500000,0.005,$F$1>1500000,0.003)} -> 0.005
A24: R | B24: Risco | C24: {=_xlfn.IFS($F$1<=150000,0.009,$F$1<=1500000,0.008,$F$1>1500000,0.0055)} -> 0.008
A25: DF | B25: Despesas Financeiras | C25: {=_xlfn.IFS($F$1<=150000,0.011,$F$1<=1500000,0.0085,$F$1>1500000,0.0085)} -> 0.0085
A26: L | B26: Lucro | C26: {=_xlfn.IFS($F$1<=150000,0.05,$F$1<=1500000,0.04,$F$1>1500000,0.03)} -> 0.04
A27: I | B27: COFINS | C27: 0.03
B28: PIS | C28: 0.0065
B29: ISS | C29: 0
B30: CRPB ( 0% ou 3,6% - Desoneração) | C30: 0
A31: TOTAL BDI 2 - FORNECIMENTO DE MATERIAIS E EQUIPAMENTOS | C31: =ROUND(((1+C22+C23+C24)*(1+C25)*(1+C26)/(1-C27-C28-C29-C30))-1,4) -> 0.1299
A33: NOTA: 1) Alíquotas do PIS e COFINS definidas pelo Decreto nº 4.524/2002. 2) Alíquota do Imposto Sobre Serviço (ISS) definida pela da Lei Municipal nº 691/1984 alterada pela Lei 1.513 de 27/12/1989 - Art. 1°. 3) Alíquota da Contribuição Previdenciária sobre Receita Bruta (CPRB) definida pela Lei 13.161/2015. Aplicado apenas a desoneração. 4) Parâmetros de cálculo do BDI, estão conforme limites do Acórdão nº 2.622/2014 - TCU Plenário (TC 036.076/2011-2)

Sheet Memorial
B2: Tapume | D2: 2 Lados | F2: Escavação poço | O2: Escavação PV
B3: Comp. | C3: =3.1+1.4+1.7+1.4+0.25+0.5+0.15 -> 8.5 | D3: =C3*2 -> 17 | F3: Comp. | G3: =3.1+1.4 -> 4.5 | O3: Comp. | P3: 2
B4: Larg. | C4: =2+0.5+0.5 -> 3 | D4: =C4*2 -> 6 | F4: Larg. | G4: 3 | O4: Larg. | P4: 2
D5: =D3+D4 -> 23 | F5: Prof. | G5: =0.25+2.4+0.5+0.2+0.05 -> 3.4 | O5: Prof. | P5: =0.2+2.05+0.31+0.25+0.05 -> 2.86
G6: =G3*G4*G5 -> 45.9 | P6: =P3*P4*P5 -> 11.44
B7: Locação
B8: Comp. | C8: =C3 -> 8.5 | F8: Pavimento - Concreto
B9: Larg. | C9: =C4 -> 3 | F9: Comp. | G9: =0.15+0.5+0.25+1.4+1.7+1.4+3.1 -> 8.5 | Q9: Poço | T9: PV | W9: BASE ABRIGO
C10: =C8*C9 -> 25.5 | F10: Larg. | G10: =2+1 -> 3 | Q10: Forma | R10: =62.76-U10-X10 -> 49.72 | T10: Forma | U10: 12 | W10: Forma | X10: 1.04
B11: LR | F11: 0.05 | G11: =G9*G10 -> 25.5 | Q11: Aço | R11: 816.92 | T11: Aço | U11: 37.26 | W11: Aço | X11: 28.96
B12: Comp. | C12: 340 | F12: Recomposição | G12: =G11*F11 -> 1.275 | Q12: Concreto 40MPa | R12: =10.88-U12-X12 -> 9.73 | T12: Concreto 40MPa | U12: 0.81 | W12: Concreto 40MPa | X12: 0.34
B13: Larg. | C13: 1 | Q13: Concreto magro | R13: 0.52 | W13: Impermeabilização | X13: =1.4*1.2+((1.4*0.2)*2)+((1.2*0.2)*2) -> 2.72
F14: Piso abrigo elétrico | J14: Impermeabilização Poço bomba | M14: Impermeabilização PV
C15: =C10+C14 -> 25.5 | F15: Comp. | G15: 1.5 | J15: Alt. | K15: Larg. | M15: Area de parede poço | N15: A=Pi x D x H
F16: Larg. | G16: 0.3 | J16: =2.9+0.75 -> 3.65 | K16: =3.1-0.25-0.25 -> 2.6 | L16: =J16*K16 -> 9.49 | N16: =PI()*1.04*(0.05+0.25+0.31+2.05+0.2) -> 9.3443532
G17: =G15*G16 -> 0.45 | J17: =2.4+0.5 -> 2.9 | K17: =2-0.25-0.25 -> 1.5 | L17: =J17*K17 -> 4.35
L18: =L16+L17 -> 13.84
L19: =(L18*2)+L22 -> 40.08
B20: Mureta energia | J20: Impermeabilização tampa Poço
B21: Comp | C21: 0.5 | J21: Comp. | K21: Larg.
B22: Alt | C22: 1.8 | J22: 3.1 | K22: 2 | L22: =(J22*K22)*2 -> 12.4
C23: =C21*C22 -> 0.9
B25: Pintura mureta
B26: =C23*2 -> 1.8 | C26: =(C22*0.22)*2 -> 0.792
C27: =B26+C26 -> 2.592

Sheet Quantitativo
A1: QUANTITATIVO
A2: ITEM | B2: DESCRIÇÃO | C2: QUANTIDADE | D2: UNIDADE
A3: 1 | B3: TUBO POLIETILENO PE 100 PN10 FAIXA OCRE PARA ESGOTO (BARRA COM 6,0 M) DE160 - L=1600 mm | C3: 1 | D3: UN
A4: 2 | B4: COLARINHO POLIETILENO INJETADO TERMOFUSAO PE 100 PN10 DE160 | C4: 1 | D4: UN
A5: 3 | B5: VALVULA GUILHOTINA BIDIRECIONAL FD LUG/SEMILUG/WAFER MANUAL CASTELO QUADRADO E VOLANTE PARA ESGOTO/AGUA BRUTA 16 BAR FURACAO PN16 DN80 | C5: 1 | D5: UN
A6: 4 | B6: TOCO DE TUBO FD FF PN10 MEDINDO 0.25M PARA ESGOTO DN150 | C6: 1 | D6: UN
A7: 5 | B7: CONJUNTO MOTOBOMBA EM LINHA (Q=3,5l/s; H=9,97mca) | C7: 1 | D7: CJ
A8: 6 | B8: TE REDUCAO FD FFF PARA ESGOTO PN16 DN100 DN80 | C8: 1 | D8: UN
A9: 7 | B9: VENTOSA COMBINADA/TRIPLICE FUNCAO PARA ESGOTO CORPO EM PRFV OU NYLON REFORCADO COM CAPACIDADE VAZAO MINIMA A 0,4 BAR DE 220,0 M3/H FLANGE PN10/16 DN100 POL4" | C9: 1 | D9: UN
A10: 8 | B10: TE FD FFF PN16 PARA ESGOTO DN80 | C10: 1 | D10: UN
A11: 9 | B11: TOCO DE TUBO FD FF PN16 MEDINDO 0.50 METROS PARA ESGOTO DN80 | C11: 1 | D11: UN | F11: 0.5
A12: 10 | B12: TOCO DE TUBO FD FF 700MM COM ABA DE VEDACAO PN16 PARA ESGOTO DN80 | C12: 1 | D12: UN | F12: 0.7
A13: 11 | B13: COLARINHO POLIETILENO INJETADO TERMOFUSAO PE 100 PN10 DE90 | C13: 1 | D13: UN
A14: 12 | B14: TUBO FD K9 FF (SOLDA INTERFERENCIA) PARA ESGOTO PN16 MEDINDO 1,20M DN80 | C14: 1 | D14: UN | F14: 1.2
A15: 13 | B15: EXTREMIDADE FD PF 700MM COM ABA DE VEDACAO PARA ESGOTO PN16 DN80 | C15: 1 | D15: UN | F15: 0.7
A16: 14 | B16: CURVA FD JE 2GS BB 22 PARA ESGOTO DN80 | C16: 1 | D16: UN
A17: 15 | B17: TUBO FD K9 PP PARA ESGOTO (0,9M) DN80 | C17: 1 | D17: UN | F17: 0.9
A18: 16 | B18: CONJUNTO MOTOBOMBA SUBMERSIVEL Q=22,9 M3/H (DRENAGEM) | C18: 1 | D18: UN | F18: =F11+F12+F14+F15+F17 -> 4
A19: 17 | B19: ADAPTADOR CURTO PPR80 BOLSA/ROSCA MACHO BSP TERMOFUSAO PN 10 DE 90 POL 3" | C19: 1 | D19: UN
A20: 18 | B20: TUBO PPR80 JS PP TERMOFUSAO (BARRA COM 6,0 METROS) PN 10 DE 90 | C20: 1 | D20: UN
A21: 19 | B21: UNIAO PPR FLANGEADA DE90 PN10 | C21: 1 | D21: UN
A22: 20 | B22: CURVA LONGA 90 POLIPROPILENO RANDOMICO (PPR) DE90 | C22: 1 | D22: UN
A23: s/n | B23: FLANGE ACO CARBONO PARA COLARINHO PEAD EPOXI ISO 12944 320UM C5M DURABILIDADE ALTA OU PP (NBR 7675/15593) PN10 DE160 DN150 | C23: 1 | D23: CJ
A24: s/n | B24: FLANGE ACO CARBONO PARA COLARINHO PEAD EPOXI ISO 12944 320UM C5M DURABILIDADE ALTA OU PP (NBR 7675/15593) PN16 DE90 DN80 | C24: 1 | D24: CJ
A25: s/n | B25: KIT PARAFUSO PORCA ARRUELA LISA ACO CARBONO ARRUELA VEDACAO FURACAO PARA ESGOTO PN10 NBR 7675 PARA FLANGE AVULSA PARA COLARINHO PEAD DN150 | C25: 1 | D25: CJ
A26: s/n | B26: KIT PARAFUSO PORCA ARRUELA LISA ACO CARBONO ARRUELA VEDACAO FURACAO PARA ESGOTO PN16 NBR 7675 PARA FLANGE AVULSA PARA COLARINHO PEAD DN80 | C26: 1 | D26: CJ
A27: s/n | B27: KIT PARAFUSO PORCA ARRUELA LISA ACO CARBONO ARRUELA VEDACAO FURACAO PN16 NBR 7675 DN80 | C27: 4 | D27: CJ
A28: s/n | B28: KIT PARAFUSO PORCA ARRUELA LISA ACO CARBONO ARRUELA VEDACAO FURACAO PN16 NBR 7675 DN100 | C28: 2 | D28: CJ
A29: s/n | B29: KIT PARAFUSO PORCA ARRUELA LISA ACO CARBONO ARRUELA VEDACAO FURACAO PARA ESGOTO PN16 PARA VALVULAS BORBOLETA WAFER AWWA C504 NBR 7675 DN80 | C29: 1 | D29: CJ
A30: s/n | B30: KIT PARAFUSO PORCA ARRUELA LISA ACO INOX ARRUELA VEDACAO FURACAO PARA ESGOTO PN10 NBR 7675 DN150 | C30: 1 | D30: CJ
B31: ABRIGO METÁLICO | E31: https://loja.bsepaineis.com.br/armarios-paineis-modulares/painel-modular-padrao/de-2200-100mm-de-altura/painel-eletrico-modular-2200-100x800x800?nocache=1782147986842
B34: CABO DE COBRE, TÊMPERA MOLE, CLASSE 5, 0,6/1KV, EPR 90º, PP TETRAPOLAR EPROTENAX GSETTE - COR PRETA 2,5MM²
B36: =LOWER(B34) -> cabo de cobre, têmpera mole, classe 5, 0,6/1kv, epr 90º, pp tetrapolar eprotenax gsette - cor preta 2,5mm²

Sheet Preços tubos e conexões
B2: Descrição | L2: Valor | M2: Valor Total
B3: TUBO TB PE100 PLO 160 PN16 SDR11 M.FG | K3: 1 | L3: 180.61 | M3: 180.61
B4: COLARINHO DE160 PN16 SDR11 M.GF | K4: 1 | L4: 117.81 | M4: 117.81
B5: TOCO TOF10/16 150 X 250 MM M.PA | K5: 1 | L5: 712.96 | M5: 712.96
B6: TE-FLS TFF10/16 100 X 80 MM M.PA | K6: 1 | L6: 666.2 | M6: 666.2
B7: TE-FLS TFF10/16/25 80 X 80 MM M.PA | K7: 1 | L7: 579.82 | M7: 579.82
B8: TUBO-FLS TFL10/16/25 80 X 700 MM AV | K8: 1 | L8: 1679.95 | M8: 1679.95
B9: COLARINHO DE 90 PN16 SDR11 M.AG | K9: 1 | L9: 71.39 | M9: 71.39
B10: TUBO-PTA-PTA TUBINTCL 150 X 1260 MM | K10: 1 | L10: 1308.15 | M10: 1308.15
B11: TUBO-FLS TFL10/16/25 80 X 700 MM AV | K11: 1 | L11: 1679.95 | M11: 1679.95
B12: CURVA-FLS C22FF10/16/25 80 MM M.PA | K12: 1 | L12: 338 | M12: 338
B13: TUBO-PTA-PTA TUBINTCL 80 X 700 MM | K13: 1 | L13: 586.74 | M13: 586.74
B14: COLARINHO DE160 PN16 SDR11 M.GF | K14: 1 | L14: 117.81 | M14: 117.81
... B58: TUBO-PTA-PTA TUBINTCL 150 X 1400 MM | K58: 1 | L58: 1173.41 | M58: 1173.41
E61: Cidade: SAO PAULO Fax: | I61: Site:
B62: I.E.: 115674165111 | J62: Vendedor: 63
G64: Bairro: | I64: ALPHAVILLE INDUSTRIA CEP: 06455000 | L64: Cidade:
A65: FAX: 00000000000 | H65: Contato: DENIO | K65: EMAIL: denio.maciel@2ssconstrucoes.com.br
B67: Descrição | J67: Unid. | M67: Valor Total
B68: TUBO-PTA-PTA TUBINTCL 150 X 1000 MM | J68: PC | M68: 935.48
B69: ARRUELA BOR. ABFNBR10 50 MM GB | J69: PC | M69: 8.56
B70: PARAF.PORC.AR G.FOGO 5/8 X 4 TP | J70: CJ | M70: 40.45
B71: ARRUELA BOR. ABFNBR10 80 MM GB | J71: PC | M71: 13.32
B72: PARAF.PORC.AR G.FOGO 5/8 X 4 TP | J72: CJ | M72: 80.9
B73: ARRUELA BOR. ABFNBR10 150 MM GB | J73: PC | M73: 25.2
B74: PARAF.PORC.AR G.FOGO ¾ X 4.½ TP | J74: CJ | M74: 128
D75: 2024.47
F80: FOB: 
C81: 10 dias A COMBINAR- sujeito à análise de INCLUSOS até 0 dias

Sheet Elétrico
A2: Item | D2: Descrição | I2: Unid. | L2: Quant. | O2: Valor
A3: 1 | D3: IMPLANTAÇÃO GERAL
A4: 1.01 | D4: ELETRODUTO/DUTO PEAD FLEXIVEL PAREDE SIMPLES, CORRUGACAO HELICOIDAL, COR PRETA, SEM ROSCA, DE 2", PARA CABEAMENTO SUBTERRANEO (NBR 15715) | I4: M | L4: 6
A5: 1.02 | D5: ELETRODUTO Ø 2" ACO CARBONO GALVANIZADO ZICAGEM POR IMERSAO A ǪUENTE, SEM ROSCA, CL PESADA (PAREDE 2,25MM), NBR 5598. BARRA DE 3,0 M-FORNECIMENTO E ASS | I5: M | L5: 12
A6: 1.03 | D6: CONDULETE TIPO LB DE ALUMÍNIO, TAMPA CEGA, Ø 2" | I6: UN. | L6: 7
A7: 1.04 | D7: CONDULETE TIPO T DE ALUMÍNIO, TAMPA CEGA, Ø 2" | I7: UN. | L7: 1
A8: 1.05 | D8: CAIXA DE CONCRETO ARMADO PRE-MOLDADO, COM FUNDO E TAMPA, DIMENSOES DE 0,40 X 0,40 X 0,40 M | I8: UN. | L8: 1
A9: 2 | D9: RELAÇÃO DE EQUIPAMENTOS ELÉTRICOS E DE AUTOMAÇÃO
A10: 2.02 | D10: PAINEL ELÉTRICO ǪCM - ǪUADRO DE COMANDO E PROTEÇÃO DE MOTORES, COM ACIONAMENTO PARA 2 MOTOR COM INVERSOR 3CV, 220V, 3F, 60HZ, INSTALAÇÃO ABRIGADA, A SER MONTADO E TESTADO CONFORME PROJETO E ESPECIFICAÇÃO TÉCNICA. | I10: UN. | L10: 1
A11: 2.03 | D11: CHAVE DE NÍVEL TIPO PERA COM CONTATO NA+NF | I11: UN. | L11: 1
A12: 3 | D12: RELAÇÃO DE SERVIÇOS ESPECÍFICOS E DE AUTOMAÇÃO
A13: 3.01 | D13: ELETRICISTA (HORISTA) | I13: H | L13: 528
A14: 3.02 | D14: AJUDANTE DE ELETRICISTA (HORISTA) | I14: H | L14: 528
A15: 3.03 | D15: PEDREIRO (HORISTA) | I15: H | L15: 176
A16: 3.04 | D16: AUXILIAR DE PEDREIRO (HORISTA) | I16: H | L16: 176
A17: 3.05 | D17: COMISSIONAMENTO E STARTUP DE ELEVATORIA COM 2 CMB (1+1) COM CLP | I17: H | L17: 80
A18: 4 | D18: IMPLANTAÇÃO ATERRAMENTO GERAL
A19: 4.01 | D19: CABO DE COBRE NU 50MM² - 7 FIOS X DN 3,00MM | I19: M | L19: 20
A20: 4.02 | D20: CAIXA DE EǪUIPOTENCIALIZAÇÃO EM TERMOPLÁSTICO COM 9 FUROS | I20: UN | L20: 1
A21: 4.03 | D21: HASTE DE ATERRAMENTO DIÂMETRO 3/4" COMPRIMENTO 3,00M | I21: UN | L21: 4 | O21: 5 | P21: =3*4 -> 12
A22: 4.04 | D22: TERMINAL ESTANHADO 1 FURO A COMPRESSÃO, REF: TEL-5150 | I22: UN | L22: 5 | P22: =2.4*5 -> 12
A23: 4.05 | D23: CONECTORES DE PRESSÃO TIPO SPLIT-BOLT, REF: TEL-5018 | I23: UN | L23: 5
A24: 4.06 | D24: CAIXA DE INSPEÇÃO EM PROPILENO DN 300MM TEL-552PP | I24: UN | L24: 1
A25: 5 | D25: LISTA DE CABOS GERAIS
A26: 5.01 | D26: CABO DE COBRE, TÊMPERA MOLE, CLASSE 5, 0,6/1KV, EPR 90º, UNIPOLAR TIPO EPROTENAX GSETTE - COR PRETA 10MM² | I26: M | L26: 36
A27: 5.02 | D27: CABO DE COBRE, TÊMPERA MOLE, CLASSE 5, 0,6/1KV, EPR 90º, UNIPOLAR TIPO EPROTENAX GSETTE - COR AZUL 10MM² | I27: M | L27: 12
A28: 5.03 | D28: CABO DE COBRE, TÊMPERA MOLE, CLASSE 5, 0,6/1KV, EPR 90º, UNIPOLAR TIPO EPROTENAX GSETTE - COR VERDE 10MM² | I28: M | L28: 12
A29: 5.04 | D29: CABO DE COBRE, TÊMPERA MOLE, CLASSE 5, 0,6/1KV, EPR 90º, PP TETRAPOLAR EPROTENAX GSETTE - COR PRETA 2,5MM² | I29: M | L29: 30
A30: 5.05 | D30: CABO DE INSTRUMENTAÇÃO COM BLINDAGEM ELETROSTÁTICA 1X[2#1,5MM²+SH] | I30: M | L30: 10
D32: CABO DE COBRE, TÊMPERA MOLE, CLASSE 5, 0,6/1KV, EPR 90º, UNIPOLAR TIPO EPROTENAX GSETTE - COR PRETA 10MM² | I32: M | L32: 36
D33: CABO DE COBRE, TÊMPERA MOLE, CLASSE 5, 0,6/1KV, EPR 90º, UNIPOLAR TIPO EPROTENAX GSETTE - COR AZUL 10MM² | I33: M | L33: 12
D34: CABO DE COBRE, TÊMPERA MOLE, CLASSE 5, 0,6/1KV, EPR 90º, UNIPOLAR TIPO EPROTENAX GSETTE - COR VERDE 10MM² | I34: M | L34: 12
D35: CABO DE COBRE, TÊMPERA MOLE, CLASSE 5, 0,6/1KV, EPR 90º, PP TETRAPOLAR EPROTENAX GSETTE - COR PRETA 2,5MM² | I35: M | L35: 30
D36: CABO DE INSTRUMENTAÇÃO COM BLINDAGEM ELETROSTÁTICA 1X[2#1,5MM²+SH] | I36: M | L36: 10

Sheet ORÇAMENTO SINTÉTICO - PA4
B1: ORÇAMENTO SINTÉTICO SEM DESONERAÇÃO FONTE: SANEPAR
B3: #VALUE! | F3: ELABORAÇÃO DE ORÇAMENTO PARA ELEVATÓRIA PA4 | I3: CIDADE: | K3: UBIRATÃ | N3: #VALUE!
I4: ESTADO: | K4: PARANÁ
I5: SISTEMA:
I6: MICROBACIA / ÁREA: | K6: PA4
I7: DATA: | K7: 46147
I8: REVISÃO: | K8: R00
I9: ELABORAÇÃO: | K9: DANIEL GAMA
I10: ENG. RESPONSÁVEL: | K10: RODRIGO A. ZANATTA
I11: CREA: | K11: SC-0680240/D
B12: Código | E12: Descrição | G12: Tipo | H12: Origem | I12: Quant. | J12: Un. Med. | K12: Valor Unitário | M12: BDI | N12: Preço Unit. C/ BDI | O12: Custo Total | P12: Preço Total C/ BDI
E13: SERVIÇOS INICIAIS | P13: =P14+P21+P30 -> 14184.988
B14: 001 | E14: CANTEIRO DE OBRAS | P14: =P15+P17+P19 -> 2953.5901
B15: 001.003 | E15: ABASTECIMENTO DE ÁGUA | K15: =[2]REF_TAB_PREÇOS_SANEPAR!I27 | M15: =IF(G15="", "", IFERROR(IF(G15="Mat", [2]BDI!C$31, IF(G15="MO", [2]BDI!C$17)), "")) | P15: =P16 -> 244.84693
B16: 001003001 | E16: Entrada provisória de água | G16: MO | H16: Sanepar | I16: 1 | J16: ud | K16: =[2]REF_TAB_PREÇOS_SANEPAR!I28 -> 196.68 | M16: =IF(G16="", "", IFERROR(IF(G16="Mat", BDI!C$31, IF(G16="MO", BDI!C$17)), "")) -> 0.2449 | N16: =IF(K16="","",K16*(1+M16)) -> 244.84693 | O16: =K16*I16 -> 196.68 | P16: =N16*I16 -> 244.84693
B17: 001.004 | E17: PROTEÇÃO DA ÁREA | K17: =[2]REF_TAB_PREÇOS_SANEPAR!I32 | M17: =IF(G17="", "", IFERROR(IF(G17="Mat", BDI!C$31, IF(G17="MO", BDI!C$17)), "")) | P17: =P18 -> 210.94103
B18: 001004004 | E18: Tapume de chapas metálicas | G18: Mat | H18: Sanepar | I18: 1 | J18: m | K18: =[2]REF_TAB_PREÇOS_SANEPAR!I36 -> 186.69 | M18: =IF(G18="", "", IFERROR(IF(G18="Mat", BDI!C$31, IF(G18="MO", BDI!C$17)), "")) -> 0.1299 | N18: =IF(K18="","",K18*(1+M18)) -> 210.94103 | O18: =K18*I18 -> 186.69 | P18: =N18*I18 -> 210.94103
B19: 001.005 | E19: PLACA DE OBRA | K19: =[2]REF_TAB_PREÇOS_SANEPAR!I37 | M19: =IF(G19="", "", IFERROR(IF(G19="Mat", BDI!C$31, IF(G19="MO", BDI!C$17)), "")) | P19: =P20 -> 2497.8021
B20: 001005001 | E20: Em chapa metálica | G20: Mat | H20: Sanepar | I20: 4 | J20: m² | K20: =[2]REF_TAB_PREÇOS_SANEPAR!I38 -> 552.66 | M20: =IF(G20="", "", IFERROR(IF(G20="Mat", BDI!C$31, IF(G20="MO", BDI!C$17)), "")) -> 0.1299 | N20: =IF(K20="","",K20*(1+M20)) -> 624.45053 | O20: =K20*I20 -> 2210.64 | P20: =N20*I20 -> 2497.8021
B21: 002 | E21: SERVIÇOS TÉCNICOS | K21: =[2]REF_TAB_PREÇOS_SANEPAR!I39 | M21: =IF(G21="", "", IFERROR(IF(G21="Mat", BDI!C$31, IF(G21="MO", BDI!C$17)), "")) | P21: =P22+P26+P28 -> 9389.9446
B22: 002.001 | E22: TOPOGRAFIA E GEODÉSIA - SERVIÇOS | K22: =[2]REF_TAB_PREÇOS_SANEPAR!I40 | M22: =IF(G22="", "", IFERROR(IF(G22="Mat", BDI!C$31, IF(G22="MO", BDI!C$17)), "")) | P22: =P23+P24+P25 -> 150.45861
B23: 002001004 | E23: Locação de furos de sondagem | G23: MO | H23: Sanepar | I23: 3 | J23: ud | K23: =[2]REF_TAB_PREÇOS_SANEPAR!I44 -> 39.04 | M23: =IF(G23="", "", IFERROR(IF(G23="Mat", BDI!C$31, IF(G23="MO", BDI!C$17)), "")) -> 0.2449 | N23: =IF(K23="","",K23*(1+M23)) -> 48.600896 | O23: =K23*I23 -> 117.12 | P23: =N23*I23 -> 145.80269
B24: 002001008 | E24: Levantamento planialtimétrico cadastral de área: 0,00 m² < área < 1.000 m² | G24: MO | H24: Sanepar | I24: 1 | J24: m² | K24: =[2]REF_TAB_PREÇOS_SANEPAR!I48 -> 1.02 | M24: =IF(G24="", "", IFERROR(IF(G24="Mat", BDI!C$31, IF(G24="MO", BDI!C$17)), "")) -> 0.2449 | N24: =IF(K24="","",K24*(1+M24)) -> 1.269798 | O24: =K24*I24 -> 1.02 | P24: =N24*I24 -> 1.269798
B25: 002001043 | E25: Locação da obra com auxílio de equipamento topográfico | G25: MO | H25: Sanepar | I25: 1 | J25: m² | K25: =[2]REF_TAB_PREÇOS_SANEPAR!I83 -> 2.72 | M25: =IF(G25="", "", IFERROR(IF(G25="Mat", BDI!C$31, IF(G25="MO", BDI!C$17)), "")) -> 0.2449 | N25: =IF(K25="","",K25*(1+M25)) -> 3.386128 | O25: =K25*I25 -> 2.72 | P25: =N25*I25 -> 3.386128
B26: 002.004 | E26: SONDAGEM A PERCUSSÃO | K26: =[2]REF_TAB_PREÇOS_SANEPAR!I138 | M26: =IF(G26="", "", IFERROR(IF(G26="Mat", BDI!C$31, IF(G26="MO", BDI!C$17)), "")) | P26: =P27 -> 9047.622
B27: 002004002 | E27: Perfuração em solo (SPT) com estadia da equipe | G27: MO | H27: Sanepar | I27: 25 | J27: m | K27: =[2]REF_TAB_PREÇOS_SANEPAR!I140 -> 290.71 | M27: =IF(G27="", "", IFERROR(IF(G27="Mat", BDI!C$31, IF(G27="MO", BDI!C$17)), "")) -> 0.2449 | N27: =IF(K27="","",K27*(1+M27)) -> 361.90488 | O27: =K27*I27 -> 7267.75 | P27: =N27*I27 -> 9047.622
B28: 002.007 | E28: CADASTRO DE OBRAS | K28: =[2]REF_TAB_PREÇOS_SANEPAR!I167 | M28: =IF(G28="", "", IFERROR(IF(G28="Mat", BDI!C$31, IF(G28="MO", BDI!C$17)), "")) | P28: =P29 -> 191.86399
B29: 002007005 | E29: Cadastro de obra localizada "As Built" | G29: MO | H29: Sanepar | I29: 1 | J29: ud | K29: =[2]REF_TAB_PREÇOS_SANEPAR!I172 -> 154.12 | M29: =IF(G29="", "", IFERROR(IF(G29="Mat", BDI!C$31, IF(G29="MO", BDI!C$17)), "")) -> 0.2449 | N29: =IF(K29="","",K29*(1+M29)) -> 191.86399 | O29: =K29*I29 -> 154.12 | P29: =N29*I29 -> 191.86399
B30: 003 | E30: SERVIÇOS PRELIMINARES | K30: =[2]REF_TAB_PREÇOS_SANEPAR!I173 | M30: =IF(G30="", "", IFERROR(IF(G30="Mat", BDI!C$31, IF(G30="MO", BDI!C$17)), "")) | P30: =P31+P33+P36 -> 1841.4532
B31: 003.002 | E31: ACESSO PROVISÓRIO | K31: =[2]REF_TAB_PREÇOS_SANEPAR!I184 | M31: =IF(G31="", "", IFERROR(IF(G31="Mat", BDI!C$31, IF(G31="MO", BDI!C$17)), "")) | P31: =P32 -> 37.658225
B32: 003002001 | E32: Acesso provisório | G32: MO | H32: Sanepar | I32: 5 | J32: m² | K32: =[2]REF_TAB_PREÇOS_SANEPAR!I185 -> 6.05 | M32: =IF(G32="", "", IFERROR(IF(G32="Mat", BDI!C$31, IF(G32="MO", BDI!C$17)), "")) -> 0.2449 | N32: =IF(K32="","",K32*(1+M32)) -> 7.531645 | O32: =K32*I32 -> 30.25 | P32: =N32*I32 -> 37.658225
B33: 003.005 | E33: SINALIZAÇÃO DE SEGURANÇA | K33: =[2]REF_TAB_PREÇOS_SANEPAR!I201 | M33: =IF(G33="", "", IFERROR(IF(G33="Mat", BDI!C$31, IF(G33="MO", BDI!C$17)), "")) | P33: =P34+P35 -> 2.417986
B34: 003005001 | E34: Fita plástica | G34: Mat | H34: Sanepar | I34: 1 | J34: m | K34: =[2]REF_TAB_PREÇOS_SANEPAR!I202 -> 0.3 | M34: =IF(G34="", "", IFERROR(IF(G34="Mat", BDI!C$31, IF(G34="MO", BDI!C$17)), "")) -> 0.1299 | N34: =IF(K34="","",K34*(1+M34)) -> 0.33897 | O34: =K34*I34 -> 0.3 | P34: =N34*I34 -> 0.33897
B35: 003005004 | E35: Tapume em tela plástica | G35: Mat | H35: Sanepar | I35: 1 | J35: m | K35: =[2]REF_TAB_PREÇOS_SANEPAR!I205 -> 1.84 | M35: =IF(G35="", "", IFERROR(IF(G35="Mat", BDI!C$31, IF(G35="MO", BDI!C$17)), "")) -> 0.1299 | N35: =IF(K35="","",K35*(1+M35)) -> 2.079016 | O35: =K35*I35 -> 1.84 | P35: =N35*I35 -> 2.079016
B36: 003.006 | E36: SINALIZAÇÃO DE TRÂNSITO | K36: =[2]REF_TAB_PREÇOS_SANEPAR!I206 | M36: =IF(G36="", "", IFERROR(IF(G36="Mat", BDI!C$31, IF(G36="MO", BDI!C$17)), "")) | P36: =P37+P38 -> 1801.377
B37: 003006001 | E37: Placa de advertência 1,00 x 1,00 m | G37: Mat | H37: Sanepar | I37: 4 | J37: ud | K37: =[2]REF_TAB_PREÇOS_SANEPAR!I207 -> 151.33 | M37: =IF(G37="", "", IFERROR(IF(G37="Mat", BDI!C$31, IF(G37="MO", BDI!C$17)), "")) -> 0.1299 | N37: =IF(K37="","",K37*(1+M37)) -> 170.98777 | O37: =K37*I37 -> 605.32 | P37: =N37*I37 -> 683.95107
B38: 003006002 | E38: Placa de advertência 1,00 x 2,00 m | G38: Mat | H38: Sanepar | I38: 4 | J38: ud | K38: =[2]REF_TAB_PREÇOS_SANEPAR!I208 -> 247.24 | M38: =IF(G38="", "", IFERROR(IF(G38="Mat", BDI!C$31, IF(G38="MO", BDI!C$17)), "")) -> 0.1299 | N38: =IF(K38="","",K38*(1+M38)) -> 279.35648 | O38: =K38*I38 -> 988.96 | P38: =N38*I38 -> 1117.4259
E39: POÇO DE SUCÇÃO E RAC | M39: =IF(G39="", "", IFERROR(IF(G39="Mat", BDI!C$31, IF(G39="MO", BDI!C$17)), "")) | P39: =P40+P45+P59+P68+P131 -> 209763.42
B40: 004 | E40: MOVIMENTO DE SOLOS | K40: =[2]REF_TAB_PREÇOS_SANEPAR!I249 | M40: =IF(G40="", "", IFERROR(IF(G40="Mat", BDI!C$31, IF(G40="MO", BDI!C$17)), "")) | P40: =P41+P43 -> 34.135158
B41: 004.007 | E41: ESCAVAÇÃO MECÂNICA, NÃO EM VALAS, EM QUALQUER TIPO DE SOLO, EXCETO ROCHA | K41: =[2]REF_TAB_PREÇOS_SANEPAR!I296 | M41: =IF(G41="", "", IFERROR(IF(G41="Mat", BDI!C$31, IF(G41="MO", BDI!C$17)), "")) | P41: =P42 -> 22.955956
...

Sheet Quantitativo PA4
B3: DESCRIÇÃO | C3: QTD | D3: VALOR | E3: UNIDADE | F3: m
B4: TUBO POLIETILENO PE 100 PN10 FAIXA OCRE PARA ESGOTO (BARRA COM 6,0 M) DE16 - L=1600 mm | C4: 1 | E4: UN | F4: =1600/1000 -> 1.6
B5: COLARINHO POLIETILENO INJETADO TERMOFUSAO PE 100 PN10 DE160 | C5: 1 | D5: =285.99*1.1 -> 314.589 | E5: UN | G5: https://www.mercadolivre.com.br/colarinho-eletrofusao-pead-pe100-sdr11-160mm/up/MLBU1726017073
B6: TOCO DE TUBO FD FF PN10 MEDINDO 0.25M PARA ESGOTO DN150 | C6: 1 | E6: UN | F6: 0.25
B7: CONJUNTO MOTOBOMBA EM LINHA | C7: 1 | E7: CJ
B8: TE REDUCAO FD FFF PARA ESGOTO DN100 DN80 | C8: 1 | E8: UN
B9: VENTOSA COMBINADA/TRIPLICE FUNCAO PARA ESGOTO CORPO EM PRFV OU NYLON REFORCADO COM CAPACIDADE VAZAO MINIMA A 0,4 BAR DE 220,0 M3/H FLANGE PN10/16 DN100 POL4” | C9: 1 | D9: =12580*1.1 -> 13838 | E9: UN | G9: https://www.instaagro.com/ventosa-combinada-triplice-func-o-com-dispositivo-anti-golpe-sp-para-esgoto-residuos-industriais-mod-c50-g-sp-4-dn-100-flange-ansi-150-corpo-aco-inox-bermad?srsltid=AfmBOop5B4mg9HZO_ju3WRa5gO9kb0qHBmGykROg6e7s1PIsyfVWx_38
B10: TE FD FFF PARA ESGOTO PN10 DN80 | C10: 1 | E10: UN
B11: TOCO DE TUBO FD FF 700MM COM ABA DE VEDACAO PN10 PARA ESGOTO DN80 | C11: 1 | E11: UN | F11: =700/1000 -> 0.7
B12: COLARINHO POLIETILENO INJETADO TERMOFUSAO PE 100 PN10 DE90 | C12: 1 | E12: UN
B13: VALVULA GUILHOTINA BIDIRECIONAL FD LUG/SEMILUG/WAFER MANUAL CASTELO QUADRADO E VOLANTE PARA ESGOTO/AGUA BRUTA 10 BAR FURACAO PN10 HASTE PROL 0.01 A 1.0M DN80 | C13: 1 | E13: UN
B14: TUBO FD K9 PF (SOLDA INTERFERENCIA) PARA ESGOTO PN10 MEDINDO 1,26M DN150 | C14: 1 | D14: =F14*1602 -> 2018.52 | E14: UN | F14: 1.26
B15: TOCO DE TUBO FD FF 700MM COM ABA DE VEDACAO PN10 PARA ESGOTO DN80 | C15: 1 | E15: UN | F15: =700/1000 -> 0.7
B16: CURVA FD FF 22 PARA ESGOTO PN10 DN80 | C16: 1 | E16: UN
B17: TUBO FD K9 PF (SOLDA INTERFERENCIA) PARA ESGOTO PN10 MEDINDO 0,70M DN80 | C17: 1 | E17: UN | F17: 0.7
B18: CONJUNTO MOTOBOMBA SUBMERSIVELQ=22,9 M3/H | C18: 1 | E18: UN
B19: ADAPTADOR CURTO PPR80 BOLSA/ROSCA MACHO BSP TERMOFUSAO PN 10 DE 90 POL 3” | C19: 1 | D19: =94.05*1.2 -> 112.86 | E19: UN | G19: https://www.plastolandia.com.br/adaptador-curto-polipropileno-bolsa-rosca-preto-3-x-90-mm
B20: UNIAO PPR FLANGEADA DE90 PN10 | C20: 1 | D20: =664.69*1.1 -> 731.159 | E20: UN | G20: https://www.mercadolivre.com.br/uniao-ppr-flangeada-dn90-amanco/up/MLBU1476326669
B21: CURVA LONGA 90 POLIPROPILENO RANDOMICO (PPR) DE90 | C21: 1 | D21: =457.35*1.1 -> 503.085 | E21: UN | G21: https://www.mercadolivre.com.br/curva-ppr-verde-longa-90-x--90mm-topfusion/up/MLBU3621032319#polycard_client=search-desktop&be_origin=backend&search_layout=grid&position=2&type=product&tracking_id=0550b0ff-cd04-494d-9508-51b655be897c&wid=MLB4325259309&sid=search
B22: TUBO PPR80 JS PP TERMOFUSAO (BARRA COM 6,0 METROS) PN 10 DE 90 | C22: 1 | D22: =647.04-1.1 -> 645.94 | E22: UN | F22: 6 | G22: https://www.plastolandia.com.br/tubo-polipropileno-solda-preto-pn-10-90-mm-x-8-20-mm-x-6-m
B23: VALVULA GUILHOTINA BIDIRECIONAL FD LUG/SEMILUG/WAFER MANUAL CASTELO QUADRADO E VOLANTE PARA ESGOTO/AGUA BRUTA 10 BAR FURACAO PN10 DN100 | C23: 1 | D23: 2193 | E23: UN
B24: FLANGE ACO CARBONO COM FURACAO PARA COLARINHO PEAD EPOXI ISO 12944 320UM C5M DURABILIDADE ALTA OU PP (NBR 7675/15593) PN10 DE90 DN80 | C24: 1 | D24: =176.53*1.1 -> 194.183 | E24: CJ | G24: https://www.mercadolivre.com.br/flange-solto-aco-din-pn1016-para-colarinho-pead-110mm/up/MLBU1750777736
B25: FLANGE ACO CARBONO PARA COLARINHO PEAD EPOXI ISO 12944 320UM C5M DURABILIDADE ALTA OU PP (NBR 7675/15593) PN10 DE160 DN150 | C25: 1 | D25: 506.94 | E25: CJ
B26: KIT PARAFUSO PORCA ARRUELA LISA ACO CARBONO ARRUELA VEDACAO FURACAO PARA ESGOTO PN10 NBR 7675 PARA FLANGE AVULSA PARA COLARINHO PEAD DN80 | C26: 1 | E26: CJ
B27: KIT PARAFUSO PORCA ARRUELA LISA ACO CARBONO ARRUELA VEDACAO FURACAO PARA ESGOTO PN10 NBR 7675 PARA FLANGE AVULSA PARA COLARINHO PEAD DN150 | C27: 1 | E27: CJ
B28: KIT PARAFUSO PORCA ARRUELA LISA ACO CARBONO ARRUELA VEDACAO FURACAO PN10 PARA VALVULAS BORBOLETA WAFER AWWA C504 NBR 7675 DN80 | C28: 1 | E28: CJ
B29: KIT PARAFUSO PORCA ARRUELA LISA ACO CARBONO ARRUELA VEDACAO FURACAO PN10 PARA VALVULAS BORBOLETA WAFER AWWA C504 NBR 7675 DN100 | C29: 1 | E29: CJ
B30: KIT PARAFUSO PORCA ARRUELA LISA ACO INOX ARRUELA VEDACAO FURACAO PARA ESGOTO PN10 NBR 7675 DN80 | C30: 5 | E30: CJ
B31: KIT PARAFUSO PORCA ARRUELA LISA ACO INOX ARRUELA VEDACAO FURACAO PARA ESGOTO PN10 NBR 7675 DN100 | C31: 1 | E31: CJ
B32: KIT PARAFUSO PORCA ARRUELA LISA ACO INOX ARRUELA VEDACAO FURACAO PARA ESGOTO PN10 NBR 7675 DN150 | C32: 1 | E32: CJ
B33: Escada tipo marinheiro PRFV sem gaiola altura menor que 3,5m | C33: 1 | D33: =674.82*2 -> 1349.64 | E33: UN | G33: https://www.mercadolivre.com.br/escada-marinheiro-de-aluminio-200-m--cor-branca/up/MLBU1136718753
B35: Tubo polietileno PE 100 PN10 faixa ocre para esgoto (rolo com 50,0 m) DE90 | D35: =58.62*1.2 -> 70.344
B36: Curva polietileno injetada 45 termofusao PE 100 PN10 DE90 | D36: =405.81*1.1 -> 446.391 | G36: https://mininco.com.br/products/curva-45-termofusao-pead-pn8-de-90mm-1?_pos=2&_sid=1553216d8&_ss=r
B37: Curva polietileno injetada 90 termofusao PE 100 PN10 DE90 | D37: =599.54*1.1 -> 659.494 | G37: https://mininco.com.br/products/curva-90-termofusao-pead-pn10-de-90mm?_pos=1&_sid=1553216d8&_ss=r
B38: Curva polietileno injetada 30 termofusao PE 100 PN10 DE90 | D38: 417.65
B39: Joelho ajustavel 0 a 12 graus polietileno PE 100 BP PN16 para eletrofusao DE90 | D39: 1141.2
B42: tubo polietileno pe 100 pn10 faixa ocre para esgoto (barra com 6,0 m) de16 - l=1600 mm | C42: 1
B43: colarinho polietileno injetado termofusao pe 100 pn10 de160 | C43: 1
B44: toco de tubo fd ff pn10 medindo 0.25m para esgoto dn150 | C44: 1
B45: conjunto motobomba em linha | C45: 1
...
